Workbook

Sheet R_lags
A1: Lag l | B1: R(l) | C1: Nombre de paires | D1: R_th(l) | E1: Erreur | F1: Erreur^2 | H1: Nobs
A2: =C_lags!A2 -> 1 | B2: =(SUMPRODUCT(OFFSET(data_prep!$E$2,A2,0,$H$2-A2,1),OFFSET(data_prep!$D$2,0,0,$H$2-A2,1))-SUMPRODUCT(OFFSET(data_prep!$E$2,0,0,$H$2-A2,1),OFFSET(data_prep!$D$2,0,0,$H$2-A2,1)))/COUNT(OFFSET(data_prep!$D$2,0,0,$H$2-A2,1)) -> 0.062262 | C2: =C_lags!C2 -> 1000 | D2: {=IF(A2<=0,"", SUMPRODUCT( INDEX(model!$B:$B,5):INDEX(model!$B:$B,4+A2), INDEX( INDEX(model!$C:$C,6):INDEX(model!$C:$C,5+A2), A2-(ROW(INDEX(model!$B:$B,5):INDEX(model!$B:$B,4+A2))-ROW(INDEX(model!$B:$B,5))) ) ) + IF(A2<model!$E$2, SUMPRODUCT( ( INDEX(model!$B:$B,6+A2):INDEX(model!$B:$B,5+model!$E$2) - INDEX(model!$B:$B,6):INDEX(model!$B:$B,5+model!$E$2-A2) ), INDEX(model!$C:$C,6):INDEX(model!$C:$C,5+model!$E$2-A2) ), 0) )} -> 0 | E2: =B2-D2 -> 0.062262 | F2: =E2^2 -> 0.0038765566 | G2: =MATCH(9.99999999999999E+307,data_prep!$E:$E) -> 1002 | H2: =$G$2-1 -> 1001
A3: =C_lags!A3 -> 2 | B3: =(SUMPRODUCT(OFFSET(data_prep!$E$2,A3,0,$H$2-A3,1),OFFSET(data_prep!$D$2,0,0,$H$2-A3,1))-SUMPRODUCT(OFFSET(data_prep!$E$2,0,0,$H$2-A3,1),OFFSET(data_prep!$D$2,0,0,$H$2-A3,1)))/COUNT(OFFSET(data_prep!$D$2,0,0,$H$2-A3,1)) -> 0.057603604 | C3: =C_lags!C3 -> 999 | D3: {=IF(A3<=0,"", SUMPRODUCT( INDEX(model!$B:$B,5):INDEX(model!$B:$B,4+A3), INDEX( INDEX(model!$C:$C,6):INDEX(model!$C:$C,5+A3), A3-(ROW(INDEX(model!$B:$B,5):INDEX(model!$B:$B,4+A3))-ROW(INDEX(model!$B:$B,5))) ) ) + IF(A3<model!$E$2, SUMPRODUCT( ( INDEX(model!$B:$B,6+A3):INDEX(model!$B:$B,5+model!$E$2) - INDEX(model!$B:$B,6):INDEX(model!$B:$B,5+model!$E$2-A3) ), INDEX(model!$C:$C,6):INDEX(model!$C:$C,5+model!$E$2-A3) ), 0) )} -> 0 | E3: =B3-D3 -> 0.057603604 | F3: =E3^2 -> 0.0033181751
A4: =C_lags!A4 -> 3 | B4: =(SUMPRODUCT(OFFSET(data_prep!$E$2,A4,0,$H$2-A4,1),OFFSET(data_prep!$D$2,0,0,$H$2-A4,1))-SUMPRODUCT(OFFSET(data_prep!$E$2,0,0,$H$2-A4,1),OFFSET(data_prep!$D$2,0,0,$H$2-A4,1)))/COUNT(OFFSET(data_prep!$D$2,0,0,$H$2-A4,1)) -> 0.056391784 | C4: =C_lags!C4 -> 998 | D4: {=IF(A4<=0,"", SUMPRODUCT( INDEX(model!$B:$B,5):INDEX(model!$B:$B,4+A4), INDEX( INDEX(model!$C:$C,6):INDEX(model!$C:$C,5+A4), A4-(ROW(INDEX(model!$B:$B,5):INDEX(model!$B:$B,4+A4))-ROW(INDEX(model!$B:$B,5))) ) ) + IF(A4<model!$E$2, SUMPRODUCT( ( INDEX(model!$B:$B,6+A4):INDEX(model!$B:$B,5+model!$E$2) - INDEX(model!$B:$B,6):INDEX(model!$B:$B,5+model!$E$2-A4) ), INDEX(model!$C:$C,6):INDEX(model!$C:$C,5+model!$E$2-A4) ), 0) )} -> 0 | E4: =B4-D4 -> 0.056391784 | F4: =E4^2 -> 0.0031800333
A5: =C_lags!A5 -> 4 | B5: =(SUMPRODUCT(OFFSET(data_prep!$E$2,A5,0,$H$2-A5,1),OFFSET(data_prep!$D$2,0,0,$H$2-A5,1))-SUMPRODUCT(OFFSET(data_prep!$E$2,0,0,$H$2-A5,1),OFFSET(data_prep!$D$2,0,0,$H$2-A5,1)))/COUNT(OFFSET(data_prep!$D$2,0,0,$H$2-A5,1)) -> 0.051438315 | C5: =C_lags!C5 -> 997 | D5: {=IF(A5<=0,"", SUMPRODUCT( INDEX(model!$B:$B,5):INDEX(model!$B:$B,4+A5), INDEX( INDEX(model!$C:$C,6):INDEX(model!$C:$C,5+A5), A5-(ROW(INDEX(model!$B:$B,5):INDEX(model!$B:$B,4+A5))-ROW(INDEX(model!$B:$B,5))) ) ) + IF(A5<model!$E$2, SUMPRODUCT( ( INDEX(model!$B:$B,6+A5):INDEX(model!$B:$B,5+model!$E$2) - INDEX(model!$B:$B,6):INDEX(model!$B:$B,5+model!$E$2-A5) ), INDEX(model!$C:$C,6):INDEX(model!$C:$C,5+model!$E$2-A5) ), 0) )} -> 0 | E5: =B5-D5 -> 0.051438315 | F5: =E5^2 -> 0.0026459002 | I5: SOLVER
A6: =C_lags!A6 -> 5 | B6: =(SUMPRODUCT(OFFSET(data_prep!$E$2,A6,0,$H$2-A6,1),OFFSET(data_prep!$D$2,0,0,$H$2-A6,1))-SUMPRODUCT(OFFSET(data_prep!$E$2,0,0,$H$2-A6,1),OFFSET(data_prep!$D$2,0,0,$H$2-A6,1)))/COUNT(OFFSET(data_prep!$D$2,0,0,$H$2-A6,1)) -> 0.054457831 | C6: =C_lags!C6 -> 996 | D6: {=IF(A6<=0,"", SUMPRODUCT( INDEX(model!$B:$B,5):INDEX(model!$B:$B,4+A6), INDEX( INDEX(model!$C:$C,6):INDEX(model!$C:$C,5+A6), A6-(ROW(INDEX(model!$B:$B,5):INDEX(model!$B:$B,4+A6))-ROW(INDEX(model!$B:$B,5))) ) ) + IF(A6<model!$E$2, SUMPRODUCT( ( INDEX(model!$B:$B,6+A6):INDEX(model!$B:$B,5+model!$E$2) - INDEX(model!$B:$B,6):INDEX(model!$B:$B,5+model!$E$2-A6) ), INDEX(model!$C:$C,6):INDEX(model!$C:$C,5+model!$E$2-A6) ), 0) )} -> 0 | E6: =B6-D6 -> 0.054457831 | F6: =E6^2 -> 0.0029656554
A7: =C_lags!A7 -> 6 | B7: =(SUMPRODUCT(OFFSET(data_prep!$E$2,A7,0,$H$2-A7,1),OFFSET(data_prep!$D$2,0,0,$H$2-A7,1))-SUMPRODUCT(OFFSET(data_prep!$E$2,0,0,$H$2-A7,1),OFFSET(data_prep!$D$2,0,0,$H$2-A7,1)))/COUNT(OFFSET(data_prep!$D$2,0,0,$H$2-A7,1)) -> 0.057326633 | C7: =C_lags!C7 -> 995 | D7: {=IF(A7<=0,"", SUMPRODUCT( INDEX(model!$B:$B,5):INDEX(model!$B:$B,4+A7), INDEX( INDEX(model!$C:$C,6):INDEX(model!$C:$C,5+A7), A7-(ROW(INDEX(model!$B:$B,5):INDEX(model!$B:$B,4+A7))-ROW(INDEX(model!$B:$B,5))) ) ) + IF(A7<model!$E$2, SUMPRODUCT( ( INDEX(model!$B:$B,6+A7):INDEX(model!$B:$B,5+model!$E$2) - INDEX(model!$B:$B,6):INDEX(model!$B:$B,5+model!$E$2-A7) ), INDEX(model!$C:$C,6):INDEX(model!$C:$C,5+model!$E$2-A7) ), 0) )} -> 0 | E7: =B7-D7 -> 0.057326633 | F7: =E7^2 -> 0.0032863429 | I7: VARIABLES | K7: CONTRAINTES
A8: =C_lags!A8 -> 7 | B8: =(SUMPRODUCT(OFFSET(data_prep!$E$2,A8,0,$H$2-A8,1),OFFSET(data_prep!$D$2,0,0,$H$2-A8,1))-SUMPRODUCT(OFFSET(data_prep!$E$2,0,0,$H$2-A8,1),OFFSET(data_prep!$D$2,0,0,$H$2-A8,1)))/COUNT(OFFSET(data_prep!$D$2,0,0,$H$2-A8,1)) -> 0.052145875 | C8: =C_lags!C8 -> 994 | D8: {=IF(A8<=0,"", SUMPRODUCT( INDEX(model!$B:$B,5):INDEX(model!$B:$B,4+A8), INDEX( INDEX(model!$C:$C,6):INDEX(model!$C:$C,5+A8), A8-(ROW(INDEX(model!$B:$B,5):INDEX(model!$B:$B,4+A8))-ROW(INDEX(model!$B:$B,5))) ) ) + IF(A8<model!$E$2, SUMPRODUCT( ( INDEX(model!$B:$B,6+A8):INDEX(model!$B:$B,5+model!$E$2) - INDEX(model!$B:$B,6):INDEX(model!$B:$B,5+model!$E$2-A8) ), INDEX(model!$C:$C,6):INDEX(model!$C:$C,5+model!$E$2-A8) ), 0) )} -> 0 | E8: =B8-D8 -> 0.052145875 | F8: =E8^2 -> 0.0027191923 | I8: G0 | J8: 0 | K8: >=0
A9: =C_lags!A9 -> 8 | B9: =(SUMPRODUCT(OFFSET(data_prep!$E$2,A9,0,$H$2-A9,1),OFFSET(data_prep!$D$2,0,0,$H$2-A9,1))-SUMPRODUCT(OFFSET(data_prep!$E$2,0,0,$H$2-A9,1),OFFSET(data_prep!$D$2,0,0,$H$2-A9,1)))/COUNT(OFFSET(data_prep!$D$2,0,0,$H$2-A9,1)) -> 0.051479355 | C9: =C_lags!C9 -> 993 | D9: {=IF(A9<=0,"", SUMPRODUCT( INDEX(model!$B:$B,5):INDEX(model!$B:$B,4+A9), INDEX( INDEX(model!$C:$C,6):INDEX(model!$C:$C,5+A9), A9-(ROW(INDEX(model!$B:$B,5):INDEX(model!$B:$B,4+A9))-ROW(INDEX(model!$B:$B,5))) ) ) + IF(A9<model!$E$2, SUMPRODUCT( ( INDEX(model!$B:$B,6+A9):INDEX(model!$B:$B,5+model!$E$2) - INDEX(model!$B:$B,6):INDEX(model!$B:$B,5+model!$E$2-A9) ), INDEX(model!$C:$C,6):INDEX(model!$C:$C,5+model!$E$2-A9) ), 0) )} -> 0 | E9: =B9-D9 -> 0.051479355 | F9: =E9^2 -> 0.002650124 | I9: beta | J9: 0.50000444 | K9: [0;2]
A10: =C_lags!A10 -> 9 | B10: =(SUMPRODUCT(OFFSET(data_prep!$E$2,A10,0,$H$2-A10,1),OFFSET(data_prep!$D$2,0,0,$H$2-A10,1))-SUMPRODUCT(OFFSET(data_prep!$E$2,0,0,$H$2-A10,1),OFFSET(data_prep!$D$2,0,0,$H$2-A10,1)))/COUNT(OFFSET(data_prep!$D$2,0,0,$H$2-A10,1)) -> 0.052504032 | C10: =C_lags!C10 -> 992 | D10: {=IF(A10<=0,"", SUMPRODUCT( INDEX(model!$B:$B,5):INDEX(model!$B:$B,4+A10), INDEX( INDEX(model!$C:$C,6):INDEX(model!$C:$C,5+A10), A10-(ROW(INDEX(model!$B:$B,5):INDEX(model!$B:$B,4+A10))-ROW(INDEX(model!$B:$B,5))) ) ) + IF(A10<model!$E$2, SUMPRODUCT( ( INDEX(model!$B:$B,6+A10):INDEX(model!$B:$B,5+model!$E$2) - INDEX(model!$B:$B,6):INDEX(model!$B:$B,5+model!$E$2-A10) ), INDEX(model!$C:$C,6):INDEX(model!$C:$C,5+model!$E$2-A10) ), 0) )} -> 0 | E10: =B10-D10 -> 0.052504032 | F10: =E10^2 -> 0.0027566734 | I10: Cible | J10: =F52 -> 0.14770385
A11: =C_lags!A11 -> 10 | B11: =(SUMPRODUCT(OFFSET(data_prep!$E$2,A11,0,$H$2-A11,1),OFFSET(data_prep!$D$2,0,0,$H$2-A11,1))-SUMPRODUCT(OFFSET(data_prep!$E$2,0,0,$H$2-A11,1),OFFSET(data_prep!$D$2,0,0,$H$2-A11,1)))/COUNT(OFFSET(data_prep!$D$2,0,0,$H$2-A11,1)) -> 0.055797175 | C11: =C_lags!C11 -> 991 | D11: {=IF(A11<=0,"", SUMPRODUCT( INDEX(model!$B:$B,5):INDEX(model!$B:$B,4+A11), INDEX( INDEX(model!$C:$C,6):INDEX(model!$C:$C,5+A11), A11-(ROW(INDEX(model!$B:$B,5):INDEX(model!$B:$B,4+A11))-ROW(INDEX(model!$B:$B,5))) ) ) + IF(A11<model!$E$2, SUMPRODUCT( ( INDEX(model!$B:$B,6+A11):INDEX(model!$B:$B,5+model!$E$2) - INDEX(model!$B:$B,6):INDEX(model!$B:$B,5+model!$E$2-A11) ), INDEX(model!$C:$C,6):INDEX(model!$C:$C,5+model!$E$2-A11) ), 0) )} -> 0 | E11: =B11-D11 -> 0.055797175 | F11: =E11^2 -> 0.0031133247
A12: =C_lags!A12 -> 11 | B12: =(SUMPRODUCT(OFFSET(data_prep!$E$2,A12,0,$H$2-A12,1),OFFSET(data_prep!$D$2,0,0,$H$2-A12,1))-SUMPRODUCT(OFFSET(data_prep!$E$2,0,0,$H$2-A12,1),OFFSET(data_prep!$D$2,0,0,$H$2-A12,1)))/COUNT(OFFSET(data_prep!$D$2,0,0,$H$2-A12,1)) -> 0.053522222 | C12: =C_lags!C12 -> 990 | D12: {=IF(A12<=0,"", SUMPRODUCT( INDEX(model!$B:$B,5):INDEX(model!$B:$B,4+A12), INDEX( INDEX(model!$C:$C,6):INDEX(model!$C:$C,5+A12), A12-(ROW(INDEX(model!$B:$B,5):INDEX(model!$B:$B,4+A12))-ROW(INDEX(model!$B:$B,5))) ) ) + IF(A12<model!$E$2, SUMPRODUCT( ( INDEX(model!$B:$B,6+A12):INDEX(model!$B:$B,5+model!$E$2) - INDEX(model!$B:$B,6):INDEX(model!$B:$B,5+model!$E$2-A12) ), INDEX(model!$C:$C,6):INDEX(model!$C:$C,5+model!$E$2-A12) ), 0) )} -> 0 | E12: =B12-D12 -> 0.053522222 | F12: =E12^2 -> 0.0028646283
A13: =C_lags!A13 -> 12 | B13: =(SUMPRODUCT(OFFSET(data_prep!$E$2,A13,0,$H$2-A13,1),OFFSET(data_prep!$D$2,0,0,$H$2-A13,1))-SUMPRODUCT(OFFSET(data_prep!$E$2,0,0,$H$2-A13,1),OFFSET(data_prep!$D$2,0,0,$H$2-A13,1)))/COUNT(OFFSET(data_prep!$D$2,0,0,$H$2-A13,1)) -> 0.049461072 | C13: =C_lags!C13 -> 989 | D13: {=IF(A13<=0,"", SUMPRODUCT( INDEX(model!$B:$B,5):INDEX(model!$B:$B,4+A13), INDEX( INDEX(model!$C:$C,6):INDEX(model!$C:$C,5+A13), A13-(ROW(INDEX(model!$B:$B,5):INDEX(model!$B:$B,4+A13))-ROW(INDEX(model!$B:$B,5))) ) ) + IF(A13<model!$E$2, SUMPRODUCT( ( INDEX(model!$B:$B,6+A13):INDEX(model!$B:$B,5+model!$E$2) - INDEX(model!$B:$B,6):INDEX(model!$B:$B,5+model!$E$2-A13) ), INDEX(model!$C:$C,6):INDEX(model!$C:$C,5+model!$E$2-A13) ), 0) )} -> 0 | E13: =B13-D13 -> 0.049461072 | F13: =E13^2 -> 0.0024463976
A14: =C_lags!A14 -> 13 | B14: =(SUMPRODUCT(OFFSET(data_prep!$E$2,A14,0,$H$2-A14,1),OFFSET(data_prep!$D$2,0,0,$H$2-A14,1))-SUMPRODUCT(OFFSET(data_prep!$E$2,0,0,$H$2-A14,1),OFFSET(data_prep!$D$2,0,0,$H$2-A14,1)))/COUNT(OFFSET(data_prep!$D$2,0,0,$H$2-A14,1)) -> 0.049741903 | C14: =C_lags!C14 -> 988 | D14: {=IF(A14<=0,"", SUMPRODUCT( INDEX(model!$B:$B,5):INDEX(model!$B:$B,4+A14), INDEX( INDEX(model!$C:$C,6):INDEX(model!$C:$C,5+A14), A14-(ROW(INDEX(model!$B:$B,5):INDEX(model!$B:$B,4+A14))-ROW(INDEX(model!$B:$B,5))) ) ) + IF(A14<model!$E$2, SUMPRODUCT( ( INDEX(model!$B:$B,6+A14):INDEX(model!$B:$B,5+model!$E$2) - INDEX(model!$B:$B,6):INDEX(model!$B:$B,5+model!$E$2-A14) ), INDEX(model!$C:$C,6):INDEX(model!$C:$C,5+model!$E$2-A14) ), 0) )} -> 0 | E14: =B14-D14 -> 0.049741903 | F14: =E14^2 -> 0.0024742569
A15: =C_lags!A15 -> 14 | B15: =(SUMPRODUCT(OFFSET(data_prep!$E$2,A15,0,$H$2-A15,1),OFFSET(data_prep!$D$2,0,0,$H$2-A15,1))-SUMPRODUCT(OFFSET(data_prep!$E$2,0,0,$H$2-A15,1),OFFSET(data_prep!$D$2,0,0,$H$2-A15,1)))/COUNT(OFFSET(data_prep!$D$2,0,0,$H$2-A15,1)) -> 0.051940223 | C15: =C_lags!C15 -> 987 | D15: {=IF(A15<=0,"", SUMPRODUCT( INDEX(model!$B:$B,5):INDEX(model!$B:$B,4+A15), INDEX( INDEX(model!$C:$C,6):INDEX(model!$C:$C,5+A15), A15-(ROW(INDEX(model!$B:$B,5):INDEX(model!$B:$B,4+A15))-ROW(INDEX(model!$B:$B,5))) ) ) + IF(A15<model!$E$2, SUMPRODUCT( ( INDEX(model!$B:$B,6+A15):INDEX(model!$B:$B,5+model!$E$2) - INDEX(model!$B:$B,6):INDEX(model!$B:$B,5+model!$E$2-A15) ), INDEX(model!$C:$C,6):INDEX(model!$C:$C,5+model!$E$2-A15) ), 0) )} -> 0 | E15: =B15-D15 -> 0.051940223 | F15: =E15^2 -> 0.0026977868
A16: =C_lags!A16 -> 15 | B16: =(SUMPRODUCT(OFFSET(data_prep!$E$2,A16,0,$H$2-A16,1),OFFSET(data_prep!$D$2,0,0,$H$2-A16,1))-SUMPRODUCT(OFFSET(data_prep!$E$2,0,0,$H$2-A16,1),OFFSET(data_prep!$D$2,0,0,$H$2-A16,1)))/COUNT(OFFSET(data_prep!$D$2,0,0,$H$2-A16,1)) -> 0.054077079 | C16: =C_lags!C16 -> 986 | D16: {=IF(A16<=0,"", SUMPRODUCT( INDEX(model!$B:$B,5):INDEX(model!$B:$B,4+A16), INDEX( INDEX(model!$C:$C,6):INDEX(model!$C:$C,5+A16), A16-(ROW(INDEX(model!$B:$B,5):INDEX(model!$B:$B,4+A16))-ROW(INDEX(model!$B:$B,5))) ) ) + IF(A16<model!$E$2, SUMPRODUCT( ( INDEX(model!$B:$B,6+A16):INDEX(model!$B:$B,5+model!$E$2) - INDEX(model!$B:$B,6):INDEX(model!$B:$B,5+model!$E$2-A16) ), INDEX(model!$C:$C,6):INDEX(model!$C:$C,5+model!$E$2-A16) ), 0) )} -> 0 | E16: =B16-D16 -> 0.054077079 | F16: =E16^2 -> 0.0029243305
A17: =C_lags!A17 -> 16 | B17: =(SUMPRODUCT(OFFSET(data_prep!$E$2,A17,0,$H$2-A17,1),OFFSET(data_prep!$D$2,0,0,$H$2-A17,1))-SUMPRODUCT(OFFSET(data_prep!$E$2,0,0,$H$2-A17,1),OFFSET(data_prep!$D$2,0,0,$H$2-A17,1)))/COUNT(OFFSET(data_prep!$D$2,0,0,$H$2-A17,1)) -> 0.052569543 | C17: =C_lags!C17 -> 985 | D17: {=IF(A17<=0,"", SUMPRODUCT( INDEX(model!$B:$B,5):INDEX(model!$B:$B,4+A17), INDEX( INDEX(model!$C:$C,6):INDEX(model!$C:$C,5+A17), A17-(ROW(INDEX(model!$B:$B,5):INDEX(model!$B:$B,4+A17))-ROW(INDEX(model!$B:$B,5))) ) ) + IF(A17<model!$E$2, SUMPRODUCT( ( INDEX(model!$B:$B,6+A17):INDEX(model!$B:$B,5+model!$E$2) - INDEX(model!$B:$B,6):INDEX(model!$B:$B,5+model!$E$2-A17) ), INDEX(model!$C:$C,6):INDEX(model!$C:$C,5+model!$E$2-A17) ), 0) )} -> 0 | E17: =B17-D17 -> 0.052569543 | F17: =E17^2 -> 0.0027635569
A18: =C_lags!A18 -> 17 | B18: =(SUMPRODUCT(OFFSET(data_prep!$E$2,A18,0,$H$2-A18,1),OFFSET(data_prep!$D$2,0,0,$H$2-A18,1))-SUMPRODUCT(OFFSET(data_prep!$E$2,0,0,$H$2-A18,1),OFFSET(data_prep!$D$2,0,0,$H$2-A18,1)))/COUNT(OFFSET(data_prep!$D$2,0,0,$H$2-A18,1)) -> 0.05270935 | C18: =C_lags!C18 -> 984 | D18: {=IF(A18<=0,"", SUMPRODUCT( INDEX(model!$B:$B,5):INDEX(model!$B:$B,4+A18), INDEX( INDEX(model!$C:$C,6):INDEX(model!$C:$C,5+A18), A18-(ROW(INDEX(model!$B:$B,5):INDEX(model!$B:$B,4+A18))-ROW(INDEX(model!$B:$B,5))) ) ) + IF(A18<model!$E$2, SUMPRODUCT( ( INDEX(model!$B:$B,6+A18):INDEX(model!$B:$B,5+model!$E$2) - INDEX(model!$B:$B,6):INDEX(model!$B:$B,5+model!$E$2-A18) ), INDEX(model!$C:$C,6):INDEX(model!$C:$C,5+model!$E$2-A18) ), 0) )} -> 0 | E18: =B18-D18 -> 0.05270935 | F18: =E18^2 -> 0.0027782755
A19: =C_lags!A19 -> 18 | B19: =(SUMPRODUCT(OFFSET(data_prep!$E$2,A19,0,$H$2-A19,1),OFFSET(data_prep!$D$2,0,0,$H$2-A19,1))-SUMPRODUCT(OFFSET(data_prep!$E$2,0,0,$H$2-A19,1),OFFSET(data_prep!$D$2,0,0,$H$2-A19,1)))/COUNT(OFFSET(data_prep!$D$2,0,0,$H$2-A19,1)) -> 0.055148525 | C19: =C_lags!C19 -> 983 | D19: {=IF(A19<=0,"", SUMPRODUCT( INDEX(model!$B:$B,5):INDEX(model!$B:$B,4+A19), INDEX( INDEX(model!$C:$C,6):INDEX(model!$C:$C,5+A19), A19-(ROW(INDEX(model!$B:$B,5):INDEX(model!$B:$B,4+A19))-ROW(INDEX(model!$B:$B,5))) ) ) + IF(A19<model!$E$2, SUMPRODUCT( ( INDEX(model!$B:$B,6+A19):INDEX(model!$B:$B,5+model!$E$2) - INDEX(model!$B:$B,6):INDEX(model!$B:$B,5+model!$E$2-A19) ), INDEX(model!$C:$C,6):INDEX(model!$C:$C,5+model!$E$2-A19) ), 0) )} -> 0 | E19: =B19-D19 -> 0.055148525 | F19: =E19^2 -> 0.0030413598
A20: =C_lags!A20 -> 19 | B20: =(SUMPRODUCT(OFFSET(data_prep!$E$2,A20,0,$H$2-A20,1),OFFSET(data_prep!$D$2,0,0,$H$2-A20,1))-SUMPRODUCT(OFFSET(data_prep!$E$2,0,0,$H$2-A20,1),OFFSET(data_prep!$D$2,0,0,$H$2-A20,1)))/COUNT(OFFSET(data_prep!$D$2,0,0,$H$2-A20,1)) -> 0.058966395 | C20: =C_lags!C20 -> 982 | D20: {=IF(A20<=0,"", SUMPRODUCT( INDEX(model!$B:$B,5):INDEX(model!$B:$B,4+A20), INDEX( INDEX(model!$C:$C,6):INDEX(model!$C:$C,5+A20), A20-(ROW(INDEX(model!$B:$B,5):INDEX(model!$B:$B,4+A20))-ROW(INDEX(model!$B:$B,5))) ) ) + IF(A20<model!$E$2, SUMPRODUCT( ( INDEX(model!$B:$B,6+A20):INDEX(model!$B:$B,5+model!$E$2) - INDEX(model!$B:$B,6):INDEX(model!$B:$B,5+model!$E$2-A20) ), INDEX(model!$C:$C,6):INDEX(model!$C:$C,5+model!$E$2-A20) ), 0) )} -> 0 | E20: =B20-D20 -> 0.058966395 | F20: =E20^2 -> 0.0034770358
A21: =C_lags!A21 -> 20 | B21: =(SUMPRODUCT(OFFSET(data_prep!$E$2,A21,0,$H$2-A21,1),OFFSET(data_prep!$D$2,0,0,$H$2-A21,1))-SUMPRODUCT(OFFSET(data_prep!$E$2,0,0,$H$2-A21,1),OFFSET(data_prep!$D$2,0,0,$H$2-A21,1)))/COUNT(OFFSET(data_prep!$D$2,0,0,$H$2-A21,1)) -> 0.059471967 | C21: =C_lags!C21 -> 981 | D21: {=IF(A21<=0,"", SUMPRODUCT( INDEX(model!$B:$B,5):INDEX(model!$B:$B,4+A21), INDEX( INDEX(model!$C:$C,6):INDEX(model!$C:$C,5+A21), A21-(ROW(INDEX(model!$B:$B,5):INDEX(model!$B:$B,4+A21))-ROW(INDEX(model!$B:$B,5))) ) ) + IF(A21<model!$E$2, SUMPRODUCT( ( INDEX(model!$B:$B,6+A21):INDEX(model!$B:$B,5+model!$E$2) - INDEX(model!$B:$B,6):INDEX(model!$B:$B,5+model!$E$2-A21) ), INDEX(model!$C:$C,6):INDEX(model!$C:$C,5+model!$E$2-A21) ), 0) )} -> 0 | E21: =B21-D21 -> 0.059471967 | F21: =E21^2 -> 0.0035369149
A22: =C_lags!A22 -> 21 | B22: =(SUMPRODUCT(OFFSET(data_prep!$E$2,A22,0,$H$2-A22,1),OFFSET(data_prep!$D$2,0,0,$H$2-A22,1))-SUMPRODUCT(OFFSET(data_prep!$E$2,0,0,$H$2-A22,1),OFFSET(data_prep!$D$2,0,0,$H$2-A22,1)))/COUNT(OFFSET(data_prep!$D$2,0,0,$H$2-A22,1)) -> 0.058489796 | C22: =C_lags!C22 -> 980 | D22: {=IF(A22<=0,"", SUMPRODUCT( INDEX(model!$B:$B,5):INDEX(model!$B:$B,4+A22), INDEX( INDEX(model!$C:$C,6):INDEX(model!$C:$C,5+A22), A22-(ROW(INDEX(model!$B:$B,5):INDEX(model!$B:$B,4+A22))-ROW(INDEX(model!$B:$B,5))) ) ) + IF(A22<model!$E$2, SUMPRODUCT( ( INDEX(model!$B:$B,6+A22):INDEX(model!$B:$B,5+model!$E$2) - INDEX(model!$B:$B,6):INDEX(model!$B:$B,5+model!$E$2-A22) ), INDEX(model!$C:$C,6):INDEX(model!$C:$C,5+model!$E$2-A22) ), 0) )} -> 0 | E22: =B22-D22 -> 0.058489796 | F22: =E22^2 -> 0.0034210562
... A51: =C_lags!A51 -> 50 | B51: =(SUMPRODUCT(OFFSET(data_prep!$E$2,A51,0,$H$2-A51,1),OFFSET(data_prep!$D$2,0,0,$H$2-A51,1))-SUMPRODUCT(OFFSET(data_prep!$E$2,0,0,$H$2-A51,1),OFFSET(data_prep!$D$2,0,0,$H$2-A51,1)))/COUNT(OFFSET(data_prep!$D$2,0,0,$H$2-A51,1)) -> 0.048256572 | C51: =C_lags!C51 -> 951 | D51: {=IF(A51<=0,"", SUMPRODUCT( INDEX(model!$B:$B,5):INDEX(model!$B:$B,4+A51), INDEX( INDEX(model!$C:$C,6):INDEX(model!$C:$C,5+A51), A51-(ROW(INDEX(model!$B:$B,5):INDEX(model!$B:$B,4+A51))-ROW(INDEX(model!$B:$B,5))) ) ) + IF(A51<model!$E$2, SUMPRODUCT( ( INDEX(model!$B:$B,6+A51):INDEX(model!$B:$B,5+model!$E$2) - INDEX(model!$B:$B,6):INDEX(model!$B:$B,5+model!$E$2-A51) ), INDEX(model!$C:$C,6):INDEX(model!$C:$C,5+model!$E$2-A51) ), 0) )} -> 0 | E51: =B51-D51 -> 0.048256572 | F51: =E51^2 -> 0.0023286967
E52: SSE | F52: =SUM(F2:F51) -> 0.14770385

Sheet data_prep
A1: transaction date (1=1day=24 hours) | B1: bid-ask spread | C1: volume of the transaction (if known) | D1: Sign of the transaction | E1: Price (before transaction) | F1: Index | G1: Dp | H1: Normalized.r | I1: Signed.dp | J1: Eff.volume | K1: Log.volume | AA1: =AVERAGEIF(C:C,">0") -> 108.25547
A2: 0.000202 | B2: 0.11 | C2: 8 | D2: -1 | E2: 100 | F2: 1 | G2: =E3-E2 -> -0.016 | H2: =IF(B2<>0,G2/B2,"") -> -0.14545455 | I2: =D2*G2 -> 0.016 | J2: =IF(C2="",$AA$1,C2) -> 8 | K2: =LN(J2) -> 2.0794415
A3: 0.00107 | B3: 0.103 | D3: 1 | E3: 99.984 | F3: 2 | G3: =E4-E3 -> 0.045 | H3: =IF(B3<>0,G3/B3,"") -> 0.4368932 | I3: =D3*G3 -> 0.045 | J3: =IF(C3="",$AA$1,C3) -> 108.25547 | K3: =LN(J3) -> 4.6844939
A4: 0.001496 | B4: 0.1015 | D4: -1 | E4: 100.029 | F4: 3 | G4: =E5-E4 -> -0.05 | H4: =IF(B4<>0,G4/B4,"") -> -0.49261084 | I4: =D4*G4 -> 0.05 | J4: =IF(C4="",$AA$1,C4) -> 108.25547 | K4: =LN(J4) -> 4.6844939
A5: 0.003336 | B5: 0.092 | D5: 1 | E5: 99.979 | F5: 4 | G5: =E6-E5 -> 0.081 | H5: =IF(B5<>0,G5/B5,"") -> 0.88043478 | I5: =D5*G5 -> 0.081 | J5: =IF(C5="",$AA$1,C5) -> 108.25547 | K5: =LN(J5) -> 4.6844939
A6: 0.003952 | B6: 0.1106 | D6: 1 | E6: 100.06 | F6: 5 | G6: =E7-E6 -> 0.1 | H6: =IF(B6<>0,G6/B6,"") -> 0.90415913 | I6: =D6*G6 -> 0.1 | J6: =IF(C6="",$AA$1,C6) -> 108.25547 | K6: =LN(J6) -> 4.6844939
A7: 0.004014 | B7: 0.1028 | D7: 1 | E7: 100.16 | F7: 6 | G7: =E8-E7 -> 0.004 | H7: =IF(B7<>0,G7/B7,"") -> 0.038910506 | I7: =D7*G7 -> 0.004 | J7: =IF(C7="",$AA$1,C7) -> 108.25547 | K7: =LN(J7) -> 4.6844939
A8: 0.004074 | B8: 0.1294 | C8: 32 | D8: 1 | E8: 100.164 | F8: 7 | G8: =E9-E8 -> 0.026 | H8: =IF(B8<>0,G8/B8,"") -> 0.20092736 | I8: =D8*G8 -> 0.026 | J8: =IF(C8="",$AA$1,C8) -> 32 | K8: =LN(J8) -> 3.4657359
A9: 0.005494 | B9: 0.0981 | D9: -1 | E9: 100.19 | F9: 8 | G9: =E10-E9 -> -0.106 | H9: =IF(B9<>0,G9/B9,"") -> -1.0805301 | I9: =D9*G9 -> 0.106 | J9: =IF(C9="",$AA$1,C9) -> 108.25547 | K9: =LN(J9) -> 4.6844939
A10: 0.005559 | B10: 0.1119 | D10: -1 | E10: 100.084 | F10: 9 | G10: =E11-E10 -> -0.063 | H10: =IF(B10<>0,G10/B10,"") -> -0.56300268 | I10: =D10*G10 -> 0.063 | J10: =IF(C10="",$AA$1,C10) -> 108.25547 | K10: =LN(J10) -> 4.6844939
A11: 0.005749 | B11: 0.0861 | D11: -1 | E11: 100.021 | F11: 10 | G11: =E12-E11 -> -0.032 | H11: =IF(B11<>0,G11/B11,"") -> -0.37166086 | I11: =D11*G11 -> 0.032 | J11: =IF(C11="",$AA$1,C11) -> 108.25547 | K11: =LN(J11) -> 4.6844939
A12: 0.008327 | B12: 0.0969 | D12: 1 | E12: 99.989 | F12: 11 | G12: =E13-E12 -> 0.069 | H12: =IF(B12<>0,G12/B12,"") -> 0.7120743 | I12: =D12*G12 -> 0.069 | J12: =IF(C12="",$AA$1,C12) -> 108.25547 | K12: =LN(J12) -> 4.6844939
A13: 0.011284 | B13: 0.1147 | D13: 1 | E13: 100.058 | F13: 12 | G13: =E14-E13 -> 0.058 | H13: =IF(B13<>0,G13/B13,"") -> 0.50566696 | I13: =D13*G13 -> 0.058 | J13: =IF(C13="",$AA$1,C13) -> 108.25547 | K13: =LN(J13) -> 4.6844939
A14: 0.011411 | B14: 0.0812 | D14: 1 | E14: 100.116 | F14: 13 | G14: =E15-E14 -> 0.02 | H14: =IF(B14<>0,G14/B14,"") -> 0.24630542 | I14: =D14*G14 -> 0.02 | J14: =IF(C14="",$AA$1,C14) -> 108.25547 | K14: =LN(J14) -> 4.6844939
A15: 0.011814 | B15: 0.0878 | D15: -1 | E15: 100.136 | F15: 14 | G15: =E16-E15 -> -0.09 | H15: =IF(B15<>0,G15/B15,"") -> -1.0250569 | I15: =D15*G15 -> 0.09 | J15: =IF(C15="",$AA$1,C15) -> 108.25547 | K15: =LN(J15) -> 4.6844939
A16: 0.012001 | B16: 0.1085 | D16: 1 | E16: 100.046 | F16: 15 | G16: =E17-E16 -> 0.111 | H16: =IF(B16<>0,G16/B16,"") -> 1.0230415 | I16: =D16*G16 -> 0.111 | J16: =IF(C16="",$AA$1,C16) -> 108.25547 | K16: =LN(J16) -> 4.6844939
A17: 0.013354 | B17: 0.105 | D17: -1 | E17: 100.157 | F17: 16 | G17: =E18-E17 -> -0.109 | H17: =IF(B17<>0,G17/B17,"") -> -1.0380952 | I17: =D17*G17 -> 0.109 | J17: =IF(C17="",$AA$1,C17) -> 108.25547 | K17: =LN(J17) -> 4.6844939
A18: 0.014393 | B18: 0.1141 | C18: 8 | D18: -1 | E18: 100.048 | F18: 17 | G18: =E19-E18 -> -0.019 | H18: =IF(B18<>0,G18/B18,"") -> -0.1665206 | I18: =D18*G18 -> 0.019 | J18: =IF(C18="",$AA$1,C18) -> 8 | K18: =LN(J18) -> 2.0794415
A19: 0.014495 | B19: 0.0905 | D19: -1 | E19: 100.029 | F19: 18 | G19: =E20-E19 -> -0.042 | H19: =IF(B19<>0,G19/B19,"") -> -0.4640884 | I19: =D19*G19 -> 0.042 | J19: =IF(C19="",$AA$1,C19) -> 108.25547 | K19: =LN(J19) -> 4.6844939
A20: 0.0149 | B20: 0.1017 | D20: -1 | E20: 99.987 | F20: 19 | G20: =E21-E20 -> -0.086 | H20: =IF(B20<>0,G20/B20,"") -> -0.84562439 | I20: =D20*G20 -> 0.086 | J20: =IF(C20="",$AA$1,C20) -> 108.25547 | K20: =LN(J20) -> 4.6844939
A21: 0.01493 | B21: 0.1099 | D21: 1 | E21: 99.901 | F21: 20 | G21: =E22-E21 -> 0.064 | H21: =IF(B21<>0,G21/B21,"") -> 0.58234759 | I21: =D21*G21 -> 0.064 | J21: =IF(C21="",$AA$1,C21) -> 108.25547 | K21: =LN(J21) -> 4.6844939
A22: 0.016575 | B22: 0.1251 | D22: 1 | E22: 99.965 | F22: 21 | G22: =E23-E22 -> 0.012 | H22: =IF(B22<>0,G22/B22,"") -> 0.095923261 | I22: =D22*G22 -> 0.012 | J22: =IF(C22="",$AA$1,C22) -> 108.25547 | K22: =LN(J22) -> 4.6844939
A23: 0.017397 | B23: 0.1184 | D23: 1 | E23: 99.977 | F23: 22 | G23: =E24-E23 -> 0.045 | H23: =IF(B23<>0,G23/B23,"") -> 0.38006757 | I23: =D23*G23 -> 0.045 | J23: =IF(C23="",$AA$1,C23) -> 108.25547 | K23: =LN(J23) -> 4.6844939
A24: 0.018022 | B24: 0.1062 | D24: 1 | E24: 100.022 | F24: 23 | G24: =E25-E24 -> 0.063 | H24: =IF(B24<>0,G24/B24,"") -> 0.59322034 | I24: =D24*G24 -> 0.063 | J24: =IF(C24="",$AA$1,C24) -> 108.25547 | K24: =LN(J24) -> 4.6844939
A25: 0.020903 | B25: 0.1001 | D25: -1 | E25: 100.085 | F25: 24 | G25: =E26-E25 -> -0.069 | H25: =IF(B25<>0,G25/B25,"") -> -0.68931069 | I25: =D25*G25 -> 0.069 | J25: =IF(C25="",$AA$1,C25) -> 108.25547 | K25: =LN(J25) -> 4.6844939
A26: 0.021006 | B26: 0.1021 | D26: 1 | E26: 100.016 | F26: 25 | G26: =E27-E26 -> 0.029 | H26: =IF(B26<>0,G26/B26,"") -> 0.28403526 | I26: =D26*G26 -> 0.029 | J26: =IF(C26="",$AA$1,C26) -> 108.25547 | K26: =LN(J26) -> 4.6844939
A27: 0.021237 | B27: 0.107 | D27: -1 | E27: 100.045 | F27: 26 | G27: =E28-E27 -> -0.061 | H27: =IF(B27<>0,G27/B27,"") -> -0.57009346 | I27: =D27*G27 -> 0.061 | J27: =IF(C27="",$AA$1,C27) -> 108.25547 | K27: =LN(J27) -> 4.6844939
A28: 0.022146 | B28: 0.0879 | D28: -1 | E28: 99.984 | F28: 27 | G28: =E29-E28 -> -0.02 | H28: =IF(B28<>0,G28/B28,"") -> -0.22753129 | I28: =D28*G28 -> 0.02 | J28: =IF(C28="",$AA$1,C28) -> 108.25547 | K28: =LN(J28) -> 4.6844939
A29: 0.022351 | B29: 0.097 | D29: -1 | E29: 99.964 | F29: 28 | G29: =E30-E29 -> -0.088 | H29: =IF(B29<>0,G29/B29,"") -> -0.90721649 | I29: =D29*G29 -> 0.088 | J29: =IF(C29="",$AA$1,C29) -> 108.25547 | K29: =LN(J29) -> 4.6844939
A30: 0.022861 | B30: 0.0978 | C30: 141 | D30: -1 | E30: 99.876 | F30: 29 | G30: =E31-E30 -> -0.075 | H30: =IF(B30<>0,G30/B30,"") -> -0.76687117 | I30: =D30*G30 -> 0.075 | J30: =IF(C30="",$AA$1,C30) -> 141 | K30: =LN(J30) -> 4.9487599
A31: 0.02367 | B31: 0.1079 | D31: -1 | E31: 99.801 | F31: 30 | G31: =E32-E31 -> -0.142 | H31: =IF(B31<>0,G31/B31,"") -> -1.3160334 | I31: =D31*G31 -> 0.142 | J31: =IF(C31="",$AA$1,C31) -> 108.25547 | K31: =LN(J31) -> 4.6844939
A32: 0.0238 | B32: 0.1007 | D32: -1 | E32: 99.659 | F32: 31 | G32: =E33-E32 -> -0.036 | H32: =IF(B32<>0,G32/B32,"") -> -0.35749752 | I32: =D32*G32 -> 0.036 | J32: =IF(C32="",$AA$1,C32) -> 108.25547 | K32: =LN(J32) -> 4.6844939
A33: 0.024168 | B33: 0.0956 | D33: 1 | E33: 99.623 | F33: 32 | G33: =E34-E33 -> 0.055 | H33: =IF(B33<>0,G33/B33,"") -> 0.57531381 | I33: =D33*G33 -> 0.055 | J33: =IF(C33="",$AA$1,C33) -> 108.25547 | K33: =LN(J33) -> 4.6844939
A34: 0.025665 | B34: 0.0929 | D34: 1 | E34: 99.678 | F34: 33 | G34: =E35-E34 -> 0.061 | H34: =IF(B34<>0,G34/B34,"") -> 0.65662002 | I34: =D34*G34 -> 0.061 | J34: =IF(C34="",$AA$1,C34) -> 108.25547 | K34: =LN(J34) -> 4.6844939
A35: 0.026211 | B35: 0.1129 | D35: 1 | E35: 99.739 | F35: 34 | G35: =E36-E35 -> 0.147 | H35: =IF(B35<>0,G35/B35,"") -> 1.3020372 | I35: =D35*G35 -> 0.147 | J35: =IF(C35="",$AA$1,C35) -> 108.25547 | K35: =LN(J35) -> 4.6844939
A36: 0.029197 | B36: 0.0959 | D36: 1 | E36: 99.886 | F36: 35 | G36: =E37-E36 -> 0.004 | H36: =IF(B36<>0,G36/B36,"") -> 0.041710115 | I36: =D36*G36 -> 0.004 | J36: =IF(C36="",$AA$1,C36) -> 108.25547 | K36: =LN(J36) -> 4.6844939
A37: 0.029759 | B37: 0.1133 | D37: -1 | E37: 99.89 | F37: 36 | G37: =E38-E37 -> -0.075 | H37: =IF(B37<>0,G37/B37,"") -> -0.6619594 | I37: =D37*G37 -> 0.075 | J37: =IF(C37="",$AA$1,C37) -> 108.25547 | K37: =LN(J37) -> 4.6844939
A38: 0.030338 | B38: 0.1055 | D38: 1 | E38: 99.815 | F38: 37 | G38: =E39-E38 -> 0.118 | H38: =IF(B38<>0,G38/B38,"") -> 1.1184834 | I38: =D38*G38 -> 0.118 | J38: =IF(C38="",$AA$1,C38) -> 108.25547 | K38: =LN(J38) -> 4.6844939
A39: 0.030341 | B39: 0.1036 | D39: 1 | E39: 99.933 | F39: 38 | G39: =E40-E39 -> 0.08 | H39: =IF(B39<>0,G39/B39,"") -> 0.77220077 | I39: =D39*G39 -> 0.08 | J39: =IF(C39="",$AA$1,C39) -> 108.25547 | K39: =LN(J39) -> 4.6844939
A40: 0.030725 | B40: 0.0973 | D40: 1 | E40: 100.013 | F40: 39 | G40: =E41-E40 -> 0.105 | H40: =IF(B40<>0,G40/B40,"") -> 1.0791367 | I40: =D40*G40 -> 0.105 | J40: =IF(C40="",$AA$1,C40) -> 108.25547 | K40: =LN(J40) -> 4.6844939
...

Sheet C_lags
A1: Lag l | B1: Autocorrelation C(l) | C1: Nombre de paires (N-l)
A2: 1 | B2: =SUMPRODUCT(data_prep!$D$2:INDEX(data_prep!$D:$D,$D$2-A2),OFFSET(data_prep!$D$2:INDEX(data_prep!$D:$D,$D$2-A2),A2,0))/COUNT(data_prep!$D$2:INDEX(data_prep!$D:$D,$D$2-A2)) -> -0.014 | C2: =$D$2-1-A2 -> 1000 | D2: =MATCH(9.99999999999999E+307,data_prep!$D:$D) -> 1002
A3: =A2+1 -> 2 | B3: =SUMPRODUCT(data_prep!$D$2:INDEX(data_prep!$D:$D,$D$2-A3),OFFSET(data_prep!$D$2:INDEX(data_prep!$D:$D,$D$2-A3),A3,0))/COUNT(data_prep!$D$2:INDEX(data_prep!$D:$D,$D$2-A3)) -> 0.031031031 | C3: =$D$2-1-A3 -> 999
A4: =A3+1 -> 3 | B4: =SUMPRODUCT(data_prep!$D$2:INDEX(data_prep!$D:$D,$D$2-A4),OFFSET(data_prep!$D$2:INDEX(data_prep!$D:$D,$D$2-A4),A4,0))/COUNT(data_prep!$D$2:INDEX(data_prep!$D:$D,$D$2-A4)) -> -0.086172345 | C4: =$D$2-1-A4 -> 998
A5: =A4+1 -> 4 | B5: =SUMPRODUCT(data_prep!$D$2:INDEX(data_prep!$D:$D,$D$2-A5),OFFSET(data_prep!$D$2:INDEX(data_prep!$D:$D,$D$2-A5),A5,0))/COUNT(data_prep!$D$2:INDEX(data_prep!$D:$D,$D$2-A5)) -> 0.03109328 | C5: =$D$2-1-A5 -> 997
A6: =A5+1 -> 5 | B6: =SUMPRODUCT(data_prep!$D$2:INDEX(data_prep!$D:$D,$D$2-A6),OFFSET(data_prep!$D$2:INDEX(data_prep!$D:$D,$D$2-A6),A6,0))/COUNT(data_prep!$D$2:INDEX(data_prep!$D:$D,$D$2-A6)) -> 0.03815261 | C6: =$D$2-1-A6 -> 996
A7: =A6+1 -> 6 | B7: =SUMPRODUCT(data_prep!$D$2:INDEX(data_prep!$D:$D,$D$2-A7),OFFSET(data_prep!$D$2:INDEX(data_prep!$D:$D,$D$2-A7),A7,0))/COUNT(data_prep!$D$2:INDEX(data_prep!$D:$D,$D$2-A7)) -> -0.075376884 | C7: =$D$2-1-A7 -> 995
A8: =A7+1 -> 7 | B8: =SUMPRODUCT(data_prep!$D$2:INDEX(data_prep!$D:$D,$D$2-A8),OFFSET(data_prep!$D$2:INDEX(data_prep!$D:$D,$D$2-A8),A8,0))/COUNT(data_prep!$D$2:INDEX(data_prep!$D:$D,$D$2-A8)) -> -0.010060362 | C8: =$D$2-1-A8 -> 994
A9: =A8+1 -> 8 | B9: =SUMPRODUCT(data_prep!$D$2:INDEX(data_prep!$D:$D,$D$2-A9),OFFSET(data_prep!$D$2:INDEX(data_prep!$D:$D,$D$2-A9),A9,0))/COUNT(data_prep!$D$2:INDEX(data_prep!$D:$D,$D$2-A9)) -> 0.049345418 | C9: =$D$2-1-A9 -> 993
A10: =A9+1 -> 9 | B10: =SUMPRODUCT(data_prep!$D$2:INDEX(data_prep!$D:$D,$D$2-A10),OFFSET(data_prep!$D$2:INDEX(data_prep!$D:$D,$D$2-A10),A10,0))/COUNT(data_prep!$D$2:INDEX(data_prep!$D:$D,$D$2-A10)) -> 0.060483871 | C10: =$D$2-1-A10 -> 992
A11: =A10+1 -> 10 | B11: =SUMPRODUCT(data_prep!$D$2:INDEX(data_prep!$D:$D,$D$2-A11),OFFSET(data_prep!$D$2:INDEX(data_prep!$D:$D,$D$2-A11),A11,0))/COUNT(data_prep!$D$2:INDEX(data_prep!$D:$D,$D$2-A11)) -> 0.021190716 | C11: =$D$2-1-A11 -> 991
A12: =A11+1 -> 11 | B12: =SUMPRODUCT(data_prep!$D$2:INDEX(data_prep!$D:$D,$D$2-A12),OFFSET(data_prep!$D$2:INDEX(data_prep!$D:$D,$D$2-A12),A12,0))/COUNT(data_prep!$D$2:INDEX(data_prep!$D:$D,$D$2-A12)) -> -0.078787879 | C12: =$D$2-1-A12 -> 990
A13: =A12+1 -> 12 | B13: =SUMPRODUCT(data_prep!$D$2:INDEX(data_prep!$D:$D,$D$2-A13),OFFSET(data_prep!$D$2:INDEX(data_prep!$D:$D,$D$2-A13),A13,0))/COUNT(data_prep!$D$2:INDEX(data_prep!$D:$D,$D$2-A13)) -> -0.01718908 | C13: =$D$2-1-A13 -> 989
A14: =A13+1 -> 13 | B14: =SUMPRODUCT(data_prep!$D$2:INDEX(data_prep!$D:$D,$D$2-A14),OFFSET(data_prep!$D$2:INDEX(data_prep!$D:$D,$D$2-A14),A14,0))/COUNT(data_prep!$D$2:INDEX(data_prep!$D:$D,$D$2-A14)) -> 0.016194332 | C14: =$D$2-1-A14 -> 988
... A51: =A50+1 -> 50 | B51: =SUMPRODUCT(data_prep!$D$2:INDEX(data_prep!$D:$D,$D$2-A51),OFFSET(data_prep!$D$2:INDEX(data_prep!$D:$D,$D$2-A51),A51,0))/COUNT(data_prep!$D$2:INDEX(data_prep!$D:$D,$D$2-A51)) -> -0.0031545741 | C51: =$D$2-1-A51 -> 951

Sheet model
B1: G0 | C1: beta | E1: L
B2: =R_lags!J8 -> 0 | C2: =R_lags!J9 -> 0.50000444 | E2: =MAX(C_lags!A:A) -> 50
A4: n | B4: G(n) | C4: C(n)
A5: =0 -> 0 | B5: =$B$2/(A5+1)^$C$2 -> 0 | C5: =1 -> 1
A6: =A5+1 -> 1 | B6: =$B$2/(A6+1)^$C$2 -> 0 | C6: {=INDEX(C_lags!$B:$B,A6+1)} -> -0.014
A7: =A6+1 -> 2 | B7: =$B$2/(A7+1)^$C$2 -> 0 | C7: {=INDEX(C_lags!$B:$B,A7+1)} -> 0.031031031
A8: =A7+1 -> 3 | B8: =$B$2/(A8+1)^$C$2 -> 0 | C8: {=INDEX(C_lags!$B:$B,A8+1)} -> -0.086172345
A9: =A8+1 -> 4 | B9: =$B$2/(A9+1)^$C$2 -> 0 | C9: {=INDEX(C_lags!$B:$B,A9+1)} -> 0.03109328
A10: =A9+1 -> 5 | B10: =$B$2/(A10+1)^$C$2 -> 0 | C10: {=INDEX(C_lags!$B:$B,A10+1)} -> 0.03815261
A11: =A10+1 -> 6 | B11: =$B$2/(A11+1)^$C$2 -> 0 | C11: {=INDEX(C_lags!$B:$B,A11+1)} -> -0.075376884
A12: =A11+1 -> 7 | B12: =$B$2/(A12+1)^$C$2 -> 0 | C12: {=INDEX(C_lags!$B:$B,A12+1)} -> -0.010060362
A13: =A12+1 -> 8 | B13: =$B$2/(A13+1)^$C$2 -> 0 | C13: {=INDEX(C_lags!$B:$B,A13+1)} -> 0.049345418
A14: =A13+1 -> 9 | B14: =$B$2/(A14+1)^$C$2 -> 0 | C14: {=INDEX(C_lags!$B:$B,A14+1)} -> 0.060483871
A15: =A14+1 -> 10 | B15: =$B$2/(A15+1)^$C$2 -> 0 | C15: {=INDEX(C_lags!$B:$B,A15+1)} -> 0.021190716
A16: =A15+1 -> 11 | B16: =$B$2/(A16+1)^$C$2 -> 0 | C16: {=INDEX(C_lags!$B:$B,A16+1)} -> -0.078787879
A17: =A16+1 -> 12 | B17: =$B$2/(A17+1)^$C$2 -> 0 | C17: {=INDEX(C_lags!$B:$B,A17+1)} -> -0.01718908
... A55: =A54+1 -> 50 | B55: =$B$2/(A55+1)^$C$2 -> 0 | C55: {=INDEX(C_lags!$B:$B,A55+1)} -> -0.0031545741
