Workbook

Sheet Estimation_1516
D2: DATE | E2: PRIX | F2: LNR1J | G2: CDF KDE | H2: x | K2: ALPHA | L2: Q ALPHA
B3: ALPHA | D3: 42006 | E3: 5.621 | G3: {=SUMPRODUCT(IF(((H3-$F$4:$F$515)/$B$10)<=-1,0,IF(((H3-$F$4:$F$515)/$B$10)>=1,1,(15/16)*(((H3-$F$4:$F$515)/$B$10)-(2/3)*((H3-$F$4:$F$515)/$B$10)^3+(1/5)*((H3-$F$4:$F$515)/$B$10)^5+8/15))))/COUNT($F$4:$F$515)} -> 0 | H3: =MIN(F4:F515)-5*$B$10 -> -0.22462855 | K3: 0.01 | L3: =$B$7 -> -0.03892855
B4: 0.05 | D4: 42009 | E4: 5.424 | F4: =LN(E4/E3) -> -0.035676033 | G4: {=SUMPRODUCT(IF(((H4-$F$4:$F$515)/$B$10)<=-1,0,IF(((H4-$F$4:$F$515)/$B$10)>=1,1,(15/16)*(((H4-$F$4:$F$515)/$B$10)-(2/3)*((H4-$F$4:$F$515)/$B$10)^3+(1/5)*((H4-$F$4:$F$515)/$B$10)^5+8/15))))/COUNT($F$4:$F$515)} -> 0 | H4: =H3+0.0003 -> -0.22432855 | K4: 0.01 | L4: =$B$7 -> -0.03892855
D5: 42010 | E5: 5.329 | F5: =LN(E5/E4) -> -0.017669947 | G5: {=SUMPRODUCT(IF(((H5-$F$4:$F$515)/$B$10)<=-1,0,IF(((H5-$F$4:$F$515)/$B$10)>=1,1,(15/16)*(((H5-$F$4:$F$515)/$B$10)-(2/3)*((H5-$F$4:$F$515)/$B$10)^3+(1/5)*((H5-$F$4:$F$515)/$B$10)^5+8/15))))/COUNT($F$4:$F$515)} -> 0 | H5: =H4+0.0003 -> -0.22402855 | K5: 0.01 | L5: =$B$7 -> -0.03892855
B6: Q ALPHA | D6: 42011 | E6: 5.224 | F6: =LN(E6/E5) -> -0.019900211 | G6: {=SUMPRODUCT(IF(((H6-$F$4:$F$515)/$B$10)<=-1,0,IF(((H6-$F$4:$F$515)/$B$10)>=1,1,(15/16)*(((H6-$F$4:$F$515)/$B$10)-(2/3)*((H6-$F$4:$F$515)/$B$10)^3+(1/5)*((H6-$F$4:$F$515)/$B$10)^5+8/15))))/COUNT($F$4:$F$515)} -> 0 | H6: =H5+0.0003 -> -0.22372855 | K6: 0.01 | L6: =$B$7 -> -0.03892855
B7: =INDEX(H:H,MATCH($B$4,G:G,1)) -> -0.03892855 | D7: 42012 | E7: 5.453 | F7: =LN(E7/E6) -> 0.042902524 | G7: {=SUMPRODUCT(IF(((H7-$F$4:$F$515)/$B$10)<=-1,0,IF(((H7-$F$4:$F$515)/$B$10)>=1,1,(15/16)*(((H7-$F$4:$F$515)/$B$10)-(2/3)*((H7-$F$4:$F$515)/$B$10)^3+(1/5)*((H7-$F$4:$F$515)/$B$10)^5+8/15))))/COUNT($F$4:$F$515)} -> 0 | H7: =H6+0.0003 -> -0.22342855 | K7: 0.01 | L7: =$B$7 -> -0.03892855
D8: 42013 | E8: 5.34 | F8: =LN(E8/E7) -> -0.020940263 | G8: {=SUMPRODUCT(IF(((H8-$F$4:$F$515)/$B$10)<=-1,0,IF(((H8-$F$4:$F$515)/$B$10)>=1,1,(15/16)*(((H8-$F$4:$F$515)/$B$10)-(2/3)*((H8-$F$4:$F$515)/$B$10)^3+(1/5)*((H8-$F$4:$F$515)/$B$10)^5+8/15))))/COUNT($F$4:$F$515)} -> 0 | H8: =H7+0.0003 -> -0.22312855 | K8: 0.01 | L8: =$B$7 -> -0.03892855
B9: BANDWIDTH | D9: 42016 | E9: 5.264 | F9: =LN(E9/E8) -> -0.014334459 | G9: {=SUMPRODUCT(IF(((H9-$F$4:$F$515)/$B$10)<=-1,0,IF(((H9-$F$4:$F$515)/$B$10)>=1,1,(15/16)*(((H9-$F$4:$F$515)/$B$10)-(2/3)*((H9-$F$4:$F$515)/$B$10)^3+(1/5)*((H9-$F$4:$F$515)/$B$10)^5+8/15))))/COUNT($F$4:$F$515)} -> 0 | H9: =H8+0.0003 -> -0.22282855 | K9: 0.01 | L9: =$B$7 -> -0.03892855
B10: =1.06*_xlfn.STDEV.S(F4:F515)*COUNT(F4:F515)^(-1/5) -> 0.0073401895 | D10: 42017 | E10: 5.4 | F10: =LN(E10/E9) -> 0.02550776 | G10: {=SUMPRODUCT(IF(((H10-$F$4:$F$515)/$B$10)<=-1,0,IF(((H10-$F$4:$F$515)/$B$10)>=1,1,(15/16)*(((H10-$F$4:$F$515)/$B$10)-(2/3)*((H10-$F$4:$F$515)/$B$10)^3+(1/5)*((H10-$F$4:$F$515)/$B$10)^5+8/15))))/COUNT($F$4:$F$515)} -> 0 | H10: =H9+0.0003 -> -0.22252855 | K10: 0.01 | L10: =$B$7 -> -0.03892855
D11: 42018 | E11: 5.311 | F11: =LN(E11/E10) -> -0.016618812 | G11: {=SUMPRODUCT(IF(((H11-$F$4:$F$515)/$B$10)<=-1,0,IF(((H11-$F$4:$F$515)/$B$10)>=1,1,(15/16)*(((H11-$F$4:$F$515)/$B$10)-(2/3)*((H11-$F$4:$F$515)/$B$10)^3+(1/5)*((H11-$F$4:$F$515)/$B$10)^5+8/15))))/COUNT($F$4:$F$515)} -> 0 | H11: =H10+0.0003 -> -0.22222855 | K11: 0.01 | L11: =$B$7 -> -0.03892855
B12: VaR | D12: 42019 | E12: 5.42 | F12: =LN(E12/E11) -> 0.020315674 | G12: {=SUMPRODUCT(IF(((H12-$F$4:$F$515)/$B$10)<=-1,0,IF(((H12-$F$4:$F$515)/$B$10)>=1,1,(15/16)*(((H12-$F$4:$F$515)/$B$10)-(2/3)*((H12-$F$4:$F$515)/$B$10)^3+(1/5)*((H12-$F$4:$F$515)/$B$10)^5+8/15))))/COUNT($F$4:$F$515)} -> 0 | H12: =H11+0.0003 -> -0.22192855 | K12: 0.01 | L12: =$B$7 -> -0.03892855
B13: =-B7 -> 0.03892855 | D13: 42020 | E13: 5.492 | F13: =LN(E13/E12) -> 0.013196672 | G13: {=SUMPRODUCT(IF(((H13-$F$4:$F$515)/$B$10)<=-1,0,IF(((H13-$F$4:$F$515)/$B$10)>=1,1,(15/16)*(((H13-$F$4:$F$515)/$B$10)-(2/3)*((H13-$F$4:$F$515)/$B$10)^3+(1/5)*((H13-$F$4:$F$515)/$B$10)^5+8/15))))/COUNT($F$4:$F$515)} -> 0 | H13: =H12+0.0003 -> -0.22162855 | K13: 0.01 | L13: =$B$7 -> -0.03892855
D14: 42023 | E14: 5.635 | F14: =LN(E14/E13) -> 0.02570466 | G14: {=SUMPRODUCT(IF(((H14-$F$4:$F$515)/$B$10)<=-1,0,IF(((H14-$F$4:$F$515)/$B$10)>=1,1,(15/16)*(((H14-$F$4:$F$515)/$B$10)-(2/3)*((H14-$F$4:$F$515)/$B$10)^3+(1/5)*((H14-$F$4:$F$515)/$B$10)^5+8/15))))/COUNT($F$4:$F$515)} -> 0 | H14: =H13+0.0003 -> -0.22132855 | K14: 0.01 | L14: =$B$7 -> -0.03892855
D15: 42024 | E15: 5.729 | F15: =LN(E15/E14) -> 0.016543848 | G15: {=SUMPRODUCT(IF(((H15-$F$4:$F$515)/$B$10)<=-1,0,IF(((H15-$F$4:$F$515)/$B$10)>=1,1,(15/16)*(((H15-$F$4:$F$515)/$B$10)-(2/3)*((H15-$F$4:$F$515)/$B$10)^3+(1/5)*((H15-$F$4:$F$515)/$B$10)^5+8/15))))/COUNT($F$4:$F$515)} -> 0 | H15: =H14+0.0003 -> -0.22102855 | K15: 0.01 | L15: =$B$7 -> -0.03892855
D16: 42025 | E16: 5.764 | F16: =LN(E16/E15) -> 0.0060906827 | G16: {=SUMPRODUCT(IF(((H16-$F$4:$F$515)/$B$10)<=-1,0,IF(((H16-$F$4:$F$515)/$B$10)>=1,1,(15/16)*(((H16-$F$4:$F$515)/$B$10)-(2/3)*((H16-$F$4:$F$515)/$B$10)^3+(1/5)*((H16-$F$4:$F$515)/$B$10)^5+8/15))))/COUNT($F$4:$F$515)} -> 0 | H16: =H15+0.0003 -> -0.22072855 | K16: 0.01 | L16: =$B$7 -> -0.03892855
D17: 42026 | E17: 5.952 | F17: =LN(E17/E16) -> 0.032095619 | G17: {=SUMPRODUCT(IF(((H17-$F$4:$F$515)/$B$10)<=-1,0,IF(((H17-$F$4:$F$515)/$B$10)>=1,1,(15/16)*(((H17-$F$4:$F$515)/$B$10)-(2/3)*((H17-$F$4:$F$515)/$B$10)^3+(1/5)*((H17-$F$4:$F$515)/$B$10)^5+8/15))))/COUNT($F$4:$F$515)} -> 0 | H17: =H16+0.0003 -> -0.22042855 | K17: 0.01 | L17: =$B$7 -> -0.03892855
D18: 42027 | E18: 5.902 | F18: =LN(E18/E17) -> -0.008436021 | G18: {=SUMPRODUCT(IF(((H18-$F$4:$F$515)/$B$10)<=-1,0,IF(((H18-$F$4:$F$515)/$B$10)>=1,1,(15/16)*(((H18-$F$4:$F$515)/$B$10)-(2/3)*((H18-$F$4:$F$515)/$B$10)^3+(1/5)*((H18-$F$4:$F$515)/$B$10)^5+8/15))))/COUNT($F$4:$F$515)} -> 0 | H18: =H17+0.0003 -> -0.22012855 | K18: 0.01 | L18: =$B$7 -> -0.03892855
D19: 42030 | E19: 5.903 | F19: =LN(E19/E18) -> 0.00016941974 | G19: {=SUMPRODUCT(IF(((H19-$F$4:$F$515)/$B$10)<=-1,0,IF(((H19-$F$4:$F$515)/$B$10)>=1,1,(15/16)*(((H19-$F$4:$F$515)/$B$10)-(2/3)*((H19-$F$4:$F$515)/$B$10)^3+(1/5)*((H19-$F$4:$F$515)/$B$10)^5+8/15))))/COUNT($F$4:$F$515)} -> 0 | H19: =H18+0.0003 -> -0.21982855 | K19: 0.01 | L19: =$B$7 -> -0.03892855
D20: 42031 | E20: 5.781 | F20: =LN(E20/E19) -> -0.020884018 | G20: {=SUMPRODUCT(IF(((H20-$F$4:$F$515)/$B$10)<=-1,0,IF(((H20-$F$4:$F$515)/$B$10)>=1,1,(15/16)*(((H20-$F$4:$F$515)/$B$10)-(2/3)*((H20-$F$4:$F$515)/$B$10)^3+(1/5)*((H20-$F$4:$F$515)/$B$10)^5+8/15))))/COUNT($F$4:$F$515)} -> 0 | H20: =H19+0.0003 -> -0.21952855 | K20: 0.01 | L20: =$B$7 -> -0.03892855
D21: 42032 | E21: 5.722 | F21: =LN(E21/E20) -> -0.010258283 | G21: {=SUMPRODUCT(IF(((H21-$F$4:$F$515)/$B$10)<=-1,0,IF(((H21-$F$4:$F$515)/$B$10)>=1,1,(15/16)*(((H21-$F$4:$F$515)/$B$10)-(2/3)*((H21-$F$4:$F$515)/$B$10)^3+(1/5)*((H21-$F$4:$F$515)/$B$10)^5+8/15))))/COUNT($F$4:$F$515)} -> 0 | H21: =H20+0.0003 -> -0.21922855 | K21: 0.01 | L21: =$B$7 -> -0.03892855
D22: 42033 | E22: 5.739 | F22: =LN(E22/E21) -> 0.0029665845 | G22: {=SUMPRODUCT(IF(((H22-$F$4:$F$515)/$B$10)<=-1,0,IF(((H22-$F$4:$F$515)/$B$10)>=1,1,(15/16)*(((H22-$F$4:$F$515)/$B$10)-(2/3)*((H22-$F$4:$F$515)/$B$10)^3+(1/5)*((H22-$F$4:$F$515)/$B$10)^5+8/15))))/COUNT($F$4:$F$515)} -> 0 | H22: =H21+0.0003 -> -0.21892855 | K22: 0.01 | L22: =$B$7 -> -0.03892855
D23: 42034 | E23: 5.652 | F23: =LN(E23/E22) -> -0.015275514 | G23: {=SUMPRODUCT(IF(((H23-$F$4:$F$515)/$B$10)<=-1,0,IF(((H23-$F$4:$F$515)/$B$10)>=1,1,(15/16)*(((H23-$F$4:$F$515)/$B$10)-(2/3)*((H23-$F$4:$F$515)/$B$10)^3+(1/5)*((H23-$F$4:$F$515)/$B$10)^5+8/15))))/COUNT($F$4:$F$515)} -> 0 | H23: =H22+0.0003 -> -0.21862855 | K23: 0.01 | L23: =$B$7 -> -0.03892855
D24: 42037 | E24: 5.675 | F24: =LN(E24/E23) -> 0.0040610985 | G24: {=SUMPRODUCT(IF(((H24-$F$4:$F$515)/$B$10)<=-1,0,IF(((H24-$F$4:$F$515)/$B$10)>=1,1,(15/16)*(((H24-$F$4:$F$515)/$B$10)-(2/3)*((H24-$F$4:$F$515)/$B$10)^3+(1/5)*((H24-$F$4:$F$515)/$B$10)^5+8/15))))/COUNT($F$4:$F$515)} -> 0 | H24: =H23+0.0003 -> -0.21832855 | K24: 0.01 | L24: =$B$7 -> -0.03892855
D25: 42038 | E25: 5.846 | F25: =LN(E25/E24) -> 0.029687103 | G25: {=SUMPRODUCT(IF(((H25-$F$4:$F$515)/$B$10)<=-1,0,IF(((H25-$F$4:$F$515)/$B$10)>=1,1,(15/16)*(((H25-$F$4:$F$515)/$B$10)-(2/3)*((H25-$F$4:$F$515)/$B$10)^3+(1/5)*((H25-$F$4:$F$515)/$B$10)^5+8/15))))/COUNT($F$4:$F$515)} -> 0 | H25: =H24+0.0003 -> -0.21802855 | K25: 0.01 | L25: =$B$7 -> -0.03892855
... D1025: 43465 | E1025: 4.119 | F1025: =LN(E1025/E1024) -> 0.0075545626 | G1025: {=SUMPRODUCT(IF(((H1025-$F$4:$F$515)/$B$10)<=-1,0,IF(((H1025-$F$4:$F$515)/$B$10)>=1,1,(15/16)*(((H1025-$F$4:$F$515)/$B$10)-(2/3)*((H1025-$F$4:$F$515)/$B$10)^3+(1/5)*((H1025-$F$4:$F$515)/$B$10)^5+8/15))))/COUNT($F$4:$F$515)} -> 0.99999621 | H1025: =H1024+0.0003 -> 0.08197145 | K1025: 0.01 | L1025: =$B$7 -> -0.03892855

Sheet Backtest
B3: Alpha | C3: =Estimation_1516!B4 -> 0.05
B4: VaR | C4: =Estimation_1516!B7 -> -0.03892855
B6: N2017-2018 | C6: =COUNTIFS(Estimation_1516!$D$4:$D$1025,">="&DATE(2017,1,1),Estimation_1516!$D$4:$D$1025,"<="&DATE(2018,12,31)) -> 510
B7: Nb Violations | C7: =COUNTIFS(Estimation_1516!$D$4:$D$1025,">="&DATE(2017,1,1),Estimation_1516!$D$4:$D$1025,"<="&DATE(2018,12,31),Estimation_1516!$F$4:$F$1025,"<"&$C$4) -> 8
B9: Prop. violations | C9: =C7/C6 -> 0.015686275
B10: % violations | C10: =C7*100/C6 -> 1.5686275

Sheet Part B
A1: alpha | B1: =Estimation_1516!B4 -> 0.05
A2: Q alpha | B2: =Estimation_1516!B7 -> -0.03892855 | D2: =Estimation_1516!F2 -> LNR1J
A3: Var | B3: =Estimation_1516!B13 -> 0.03892855
D4: =Estimation_1516!F4 -> -0.035676033
A5: ES | B5: =-1*AVERAGEIF(D4:D1025,"<="&$B$2) -> 0.054517571 | D5: =Estimation_1516!F5 -> -0.017669947
D6: =Estimation_1516!F6 -> -0.019900211
D7: =Estimation_1516!F7 -> 0.042902524
D8: =Estimation_1516!F8 -> -0.020940263
D9: =Estimation_1516!F9 -> -0.014334459
D10: =Estimation_1516!F10 -> 0.02550776
D11: =Estimation_1516!F11 -> -0.016618812
D12: =Estimation_1516!F12 -> 0.020315674
D13: =Estimation_1516!F13 -> 0.013196672
D14: =Estimation_1516!F14 -> 0.02570466
D15: =Estimation_1516!F15 -> 0.016543848
D16: =Estimation_1516!F16 -> 0.0060906827
D17: =Estimation_1516!F17 -> 0.032095619
... D1025: =Estimation_1516!F1025 -> 0.0075545626

Sheet Part C
B1: LNR1J | D1: ascending order | F1: Losses | G1: abs losses | I1: gain | K1: losses: | R1: gain
K2: n : | L2: =521-3+1 -> 519 | R2: n : | S2: 503
B3: =Estimation_1516!F4 -> -0.035676033 | D3: {=_xlfn._xlws.SORT(B3:B1024)} -> -0.1879276 | F3: {=_xlfn._xlws.SORT(D3:D521,,-1)} -> -0.00013797861 | G3: =-1*F3 -> 0.00013797861 | I3: {=D522:D1024} -> 0 | K3: k : | L3: =ROUND(SQRT(L2),0) -> 23 | R3: k : | S3: =ROUND(SQRT(S2),0) -> 22
B4: =Estimation_1516!F5 -> -0.017669947 | D4: -0.071585638 | F4: -0.00018589088 | G4: =-1*F4 -> 0.00018589088 | I4: 0 | K4: n-k+1 | L4: =L2-L3+1 -> 497 | R4: n-k+1 | S4: =S2-S3+1 -> 482
B5: =Estimation_1516!F6 -> -0.019900211 | D5: -0.065422211 | F5: -0.00023113371 | G5: =-1*F5 -> 0.00023113371 | I5: 0 | K5: n-2*k+1 | L5: =L2-2*L3+1 -> 474 | R5: n-2*k+1 | S5: =S2-2*S3+1 -> 460
B6: =Estimation_1516!F7 -> 0.042902524 | D6: -0.063416816 | F6: -0.00028085943 | G6: =-1*F6 -> 0.00028085943 | I6: 0 | K6: n-4*k+1 | L6: =L2-4*L3+1 -> 428 | R6: n-4*k+1 | S6: =S2-4*S3+1 -> 416
B7: =Estimation_1516!F8 -> -0.020940263 | D7: -0.062582343 | F7: -0.00030367446 | G7: =-1*F7 -> 0.00030367446 | I7: 0 | K7: X(n-k+1) | L7: =G499 -> 0.045827033 | R7: X(n-k+1) | S7: =I484 -> 0.042387034
B8: =Estimation_1516!F9 -> -0.014334459 | D8: -0.060400933 | F8: -0.00031245118 | G8: =-1*F8 -> 0.00031245118 | I8: 0.00016941974 | K8: X(n-2k+1) | L8: =G476 -> 0.033211853 | R8: X(n-2k+1) | S8: =I462 -> 0.032190507
B9: =Estimation_1516!F10 -> 0.02550776 | D9: -0.058733805 | F9: -0.00040096231 | G9: =-1*F9 -> 0.00040096231 | I9: 0.00017644464 | K9: X(n-4k+1) | L9: =G430 -> 0.02369503 | R9: X(n-4k+1) | S9: =I418 -> 0.025947166
B10: =Estimation_1516!F11 -> -0.016618812 | D10: -0.057141486 | F10: -0.00043554008 | G10: =-1*F10 -> 0.00043554008 | I10: 0.00017954933
B11: =Estimation_1516!F12 -> 0.020315674 | D11: -0.056223126 | F11: -0.00057587102 | G11: =-1*F11 -> 0.00057587102 | I11: 0.00018390805 | K11: estimator | L11: =(1/LN(2))*LN((L7-L8)/(L8-L9)) -> 0.4066089 | R11: estimator | S11: =(1/LN(2))*LN((S7-S8)/(S8-S9)) -> 0.70768785
B12: =Estimation_1516!F13 -> 0.013196672 | D12: -0.056164829 | F12: -0.00059934074 | G12: =-1*F12 -> 0.00059934074 | I12: 0.00032472804
B13: =Estimation_1516!F14 -> 0.02570466 | D13: -0.055557882 | F13: -0.0006018658 | G13: =-1*F13 -> 0.0006018658 | I13: 0.0003412387
B14: =Estimation_1516!F15 -> 0.016543848 | D14: -0.054303294 | F14: -0.00066566819 | G14: =-1*F14 -> 0.00066566819 | I14: 0.00042096401 | K14: p | L14: 0.9 | M14: 0.95 | N14: 0.99 | O14: 0.995
B15: =Estimation_1516!F16 -> 0.0060906827 | D15: -0.054246103 | F15: -0.00066867271 | G15: =-1*F15 -> 0.00066867271 | I15: 0.00044626256 | K15: Var(p) | L15: =$L$7+($L$7-$L$8)*(($L$3/($L$2*(1-L$14)))^($L$11)-1)/(1-2^(-$L$11)) -> 0.03135642 | M15: =$L$7+($L$7-$L$8)*(($L$3/($L$2*(1-M$14)))^($L$11)-1)/(1-2^(-$L$11)) -> 0.043367534 | N15: =$L$7+($L$7-$L$8)*(($L$3/($L$2*(1-N$14)))^($L$11)-1)/(1-2^(-$L$11)) -> 0.08855543 | O15: =$L$7+($L$7-$L$8)*(($L$3/($L$2*(1-O$14)))^($L$11)-1)/(1-2^(-$L$11)) -> 0.11918862
B16: =Estimation_1516!F17 -> 0.032095619 | D16: -0.052619429 | F16: -0.00070636437 | G16: =-1*F16 -> 0.00070636437 | I16: 0.00048563336
B17: =Estimation_1516!F18 -> -0.008436021 | D17: -0.051416947 | F17: -0.0007104796 | G17: =-1*F17 -> 0.0007104796 | I17: 0.00056242971
B18: =Estimation_1516!F19 -> 0.00016941974 | D18: -0.050390747 | F18: -0.00077742366 | G18: =-1*F18 -> 0.00077742366 | I18: 0.00056609116
B19: =Estimation_1516!F20 -> -0.020884018 | D19: -0.049459801 | F19: -0.00085677572 | G19: =-1*F19 -> 0.00085677572 | I19: 0.00060944644
B20: =Estimation_1516!F21 -> -0.010258283 | D20: -0.049018709 | F20: -0.00088809953 | G20: =-1*F20 -> 0.00088809953 | I20: 0.00063552592
B21: =Estimation_1516!F22 -> 0.0029665845 | D21: -0.047281534 | F21: -0.00090950438 | G21: =-1*F21 -> 0.00090950438 | I21: 0.00064662143
B22: =Estimation_1516!F23 -> -0.015275514 | D22: -0.046552025 | F22: -0.00092506945 | G22: =-1*F22 -> 0.00092506945 | I22: 0.000653239
B23: =Estimation_1516!F24 -> 0.0040610985 | D23: -0.046419817 | F23: -0.0012022845 | G23: =-1*F23 -> 0.0012022845 | I23: 0.00070658897
B24: =Estimation_1516!F25 -> 0.029687103 | D24: -0.046029413 | F24: -0.001271456 | G24: =-1*F24 -> 0.001271456 | I24: 0.00074377095
B25: =Estimation_1516!F26 -> -0.01031646 | D25: -0.045827033 | F25: -0.0012726696 | G25: =-1*F25 -> 0.0012726696 | I25: 0.00077399385
B26: =Estimation_1516!F27 -> -0.0036360528 | D26: -0.045689743 | F26: -0.0013409321 | G26: =-1*F26 -> 0.0013409321 | I26: 0.00078094498
B27: =Estimation_1516!F28 -> 0.014978329 | D27: -0.04558606 | F27: -0.0013766733 | G27: =-1*F27 -> 0.0013766733 | I27: 0.00086592587
... B505: =Estimation_1516!F506 -> -0.013882685 | D505: -0.00085677572 | F505: -0.049459801 | G505: =-1*F505 -> 0.049459801 | I505: 0.086435804
B506: =Estimation_1516!F507 -> -0.012378253 | D506: -0.00077742366 | F506: -0.050390747 | G506: =-1*F506 -> 0.050390747
B507: =Estimation_1516!F508 -> 0.015541929 | D507: -0.0007104796 | F507: -0.051416947 | G507: =-1*F507 -> 0.051416947
B508: =Estimation_1516!F509 -> 0.0029684623 | D508: -0.00070636437 | F508: -0.052619429 | G508: =-1*F508 -> 0.052619429
B509: =Estimation_1516!F510 -> 0.0040673009 | D509: -0.00066867271 | F509: -0.054246103 | G509: =-1*F509 -> 0.054246103
B510: =Estimation_1516!F511 -> -0.0081512122 | D510: -0.00066566819 | F510: -0.054303294 | G510: =-1*F510 -> 0.054303294
B511: =Estimation_1516!F512 -> 0.00074377095 | D511: -0.0006018658 | F511: -0.055557882 | G511: =-1*F511 -> 0.055557882
B512: =Estimation_1516!F513 -> -0.00018589088 | D512: -0.00059934074 | F512: -0.056164829 | G512: =-1*F512 -> 0.056164829
B513: =Estimation_1516!F514 -> -0.0095265501 | D513: -0.00057587102 | F513: -0.056223126 | G513: =-1*F513 -> 0.056223126
B514: =Estimation_1516!F515 -> 0.0059880418 | D514: -0.00043554008 | F514: -0.057141486 | G514: =-1*F514 -> 0.057141486
B515: =Estimation_1516!F516 -> 0.0074349785 | D515: -0.00040096231 | F515: -0.058733805 | G515: =-1*F515 -> 0.058733805
B516: =Estimation_1516!F517 -> 0.03993271 | D516: -0.00031245118 | F516: -0.060400933 | G516: =-1*F516 -> 0.060400933
B517: =Estimation_1516!F518 -> 0.0037296909 | D517: -0.00030367446 | F517: -0.062582343 | G517: =-1*F517 -> 0.062582343
...
